Workbook

Sheet Dashboard
A1: Interview prep tracker
A2: Starts 11 Oct 2026. Amazon and Microsoft, SDE-2. Fill in the yellow cells on the other tabs; this page updates itself.
A4: Metric | B4: Done | C4: Target | D4: Progress | F4: Topic | G4: When | H4: 150 solved | I4: 150 total | J4: 250 solved | K4: 250 total
A5: NeetCode 150 solved (core goal) | B5: =COUNTIFS('DSA Problems'!G2:G251,"NeetCode 150",'DSA Problems'!H2:H251,"Solved") -> 0 | C5: 150 | D5: =IFERROR(B5/C5,0) -> 0 | F5: Arrays & Hashing | G5: Week 1 (quick pass) | H5: =COUNTIFS('DSA Problems'!B2:B251,F5,'DSA Problems'!G2:G251,"NeetCode 150",'DSA Problems'!H2:H251,"Solved") -> 0 | I5: =COUNTIFS('DSA Problems'!B2:B251,F5,'DSA Problems'!G2:G251,"NeetCode 150") -> 9 | J5: =COUNTIFS('DSA Problems'!B2:B251,F5,'DSA Problems'!H2:H251,"Solved") -> 0 | K5: =COUNTIF('DSA Problems'!B2:B251,F5) -> 22
A6: NeetCode 250 solved (stretch) | B6: =COUNTIF('DSA Problems'!H2:H251,"Solved") -> 0 | C6: 250 | D6: =IFERROR(B6/C6,0) -> 0 | F6: Two Pointers | G6: Week 1 | H6: =COUNTIFS('DSA Problems'!B2:B251,F6,'DSA Problems'!G2:G251,"NeetCode 150",'DSA Problems'!H2:H251,"Solved") -> 0 | I6: =COUNTIFS('DSA Problems'!B2:B251,F6,'DSA Problems'!G2:G251,"NeetCode 150") -> 5 | J6: =COUNTIFS('DSA Problems'!B2:B251,F6,'DSA Problems'!H2:H251,"Solved") -> 0 | K6: =COUNTIF('DSA Problems'!B2:B251,F6) -> 13
A7: Marked to revisit | B7: =COUNTIF('DSA Problems'!H2:H251,"Revisit") -> 0 | F7: Sliding Window | G7: Week 1 | H7: =COUNTIFS('DSA Problems'!B2:B251,F7,'DSA Problems'!G2:G251,"NeetCode 150",'DSA Problems'!H2:H251,"Solved") -> 0 | I7: =COUNTIFS('DSA Problems'!B2:B251,F7,'DSA Problems'!G2:G251,"NeetCode 150") -> 6 | J7: =COUNTIFS('DSA Problems'!B2:B251,F7,'DSA Problems'!H2:H251,"Solved") -> 0 | K7: =COUNTIF('DSA Problems'!B2:B251,F7) -> 9
A8: Problems logged in Daily Log | B8: =SUM('Daily Log'!O2:O93) -> 0 | F8: Stack | G8: Week 1 | H8: =COUNTIFS('DSA Problems'!B2:B251,F8,'DSA Problems'!G2:G251,"NeetCode 150",'DSA Problems'!H2:H251,"Solved") -> 0 | I8: =COUNTIFS('DSA Problems'!B2:B251,F8,'DSA Problems'!G2:G251,"NeetCode 150") -> 7 | J8: =COUNTIFS('DSA Problems'!B2:B251,F8,'DSA Problems'!H2:H251,"Solved") -> 0 | K8: =COUNTIF('DSA Problems'!B2:B251,F8) -> 15
A9: Gen AI course hours | B9: =SUM('Daily Log'!P2:P93) -> 0 | C9: 70 | D9: =IFERROR(B9/C9,0) -> 0 | F9: Binary Search | G9: Week 2 | H9: =COUNTIFS('DSA Problems'!B2:B251,F9,'DSA Problems'!G2:G251,"NeetCode 150",'DSA Problems'!H2:H251,"Solved") -> 0 | I9: =COUNTIFS('DSA Problems'!B2:B251,F9,'DSA Problems'!G2:G251,"NeetCode 150") -> 7 | J9: =COUNTIFS('DSA Problems'!B2:B251,F9,'DSA Problems'!H2:H251,"Solved") -> 0 | K9: =COUNTIF('DSA Problems'!B2:B251,F9) -> 14
A10: Plan topics completed | B10: =COUNTIF('Weekly Plan'!F2:F54,"Yes") -> 0 | C10: =COUNTA('Weekly Plan'!D2:D54) -> 53 | D10: =IFERROR(B10/C10,0) -> 0 | F10: Linked List | G10: Week 2 | H10: =COUNTIFS('DSA Problems'!B2:B251,F10,'DSA Problems'!G2:G251,"NeetCode 150",'DSA Problems'!H2:H251,"Solved") -> 0 | I10: =COUNTIFS('DSA Problems'!B2:B251,F10,'DSA Problems'!G2:G251,"NeetCode 150") -> 11 | J10: =COUNTIFS('DSA Problems'!B2:B251,F10,'DSA Problems'!H2:H251,"Solved") -> 0 | K10: =COUNTIF('DSA Problems'!B2:B251,F10) -> 14
A11: DSA topics | B11: =COUNTIFS('Weekly Plan'!C2:C54,"DSA",'Weekly Plan'!F2:F54,"Yes") -> 0 | C11: =COUNTIF('Weekly Plan'!C2:C54,"DSA") -> 22 | D11: =IFERROR(B11/C11,0) -> 0 | F11: Trees | G11: Week 3 | H11: =COUNTIFS('DSA Problems'!B2:B251,F11,'DSA Problems'!G2:G251,"NeetCode 150",'DSA Problems'!H2:H251,"Solved") -> 0 | I11: =COUNTIFS('DSA Problems'!B2:B251,F11,'DSA Problems'!G2:G251,"NeetCode 150") -> 15 | J11: =COUNTIFS('DSA Problems'!B2:B251,F11,'DSA Problems'!H2:H251,"Solved") -> 0 | K11: =COUNTIF('DSA Problems'!B2:B251,F11) -> 23
A12: HLD topics | B12: =COUNTIFS('Weekly Plan'!C2:C54,"HLD",'Weekly Plan'!F2:F54,"Yes") -> 0 | C12: =COUNTIF('Weekly Plan'!C2:C54,"HLD") -> 17 | D12: =IFERROR(B12/C12,0) -> 0 | F12: Heap / Priority Queue | G12: Week 4 | H12: =COUNTIFS('DSA Problems'!B2:B251,F12,'DSA Problems'!G2:G251,"NeetCode 150",'DSA Problems'!H2:H251,"Solved") -> 0 | I12: =COUNTIFS('DSA Problems'!B2:B251,F12,'DSA Problems'!G2:G251,"NeetCode 150") -> 7 | J12: =COUNTIFS('DSA Problems'!B2:B251,F12,'DSA Problems'!H2:H251,"Solved") -> 0 | K12: =COUNTIF('DSA Problems'!B2:B251,F12) -> 12
A13: LLD topics | B13: =COUNTIFS('Weekly Plan'!C2:C54,"LLD",'Weekly Plan'!F2:F54,"Yes") -> 0 | C13: =COUNTIF('Weekly Plan'!C2:C54,"LLD") -> 14 | D13: =IFERROR(B13/C13,0) -> 0 | F13: Tries | G13: Week 4 | H13: =COUNTIFS('DSA Problems'!B2:B251,F13,'DSA Problems'!G2:G251,"NeetCode 150",'DSA Problems'!H2:H251,"Solved") -> 0 | I13: =COUNTIFS('DSA Problems'!B2:B251,F13,'DSA Problems'!G2:G251,"NeetCode 150") -> 3 | J13: =COUNTIFS('DSA Problems'!B2:B251,F13,'DSA Problems'!H2:H251,"Solved") -> 0 | K13: =COUNTIF('DSA Problems'!B2:B251,F13) -> 4
A14: Behavioral stories written | B14: =COUNTIF(Milestones!C13:C24,"Yes") -> 0 | C14: 12 | D14: =IFERROR(B14/C14,0) -> 0 | F14: Backtracking | G14: Week 4 | H14: =COUNTIFS('DSA Problems'!B2:B251,F14,'DSA Problems'!G2:G251,"NeetCode 150",'DSA Problems'!H2:H251,"Solved") -> 0 | I14: =COUNTIFS('DSA Problems'!B2:B251,F14,'DSA Problems'!G2:G251,"NeetCode 150") -> 9 | J14: =COUNTIFS('DSA Problems'!B2:B251,F14,'DSA Problems'!H2:H251,"Solved") -> 0 | K14: =COUNTIF('DSA Problems'!B2:B251,F14) -> 16
A15: Milestones and checkpoints | B15: =COUNTIF(Milestones!C2:C10,"Yes") -> 0 | C15: =COUNTA(Milestones!B2:B10) -> 9 | D15: =IFERROR(B15/C15,0) -> 0 | F15: Graphs | G15: Week 5 | H15: =COUNTIFS('DSA Problems'!B2:B251,F15,'DSA Problems'!G2:G251,"NeetCode 150",'DSA Problems'!H2:H251,"Solved") -> 0 | I15: =COUNTIFS('DSA Problems'!B2:B251,F15,'DSA Problems'!G2:G251,"NeetCode 150") -> 13 | J15: =COUNTIFS('DSA Problems'!B2:B251,F15,'DSA Problems'!H2:H251,"Solved") -> 0 | K15: =COUNTIF('DSA Problems'!B2:B251,F15) -> 21
A16: Study slots completed | B16: =SUM('Daily Log'!M2:M93) -> 0 | C16: =SUM('Daily Log'!N2:N93) -> 484 | D16: =IFERROR(B16/C16,0) -> 0 | F16: Advanced Graphs | G16: Week 5 | H16: =COUNTIFS('DSA Problems'!B2:B251,F16,'DSA Problems'!G2:G251,"NeetCode 150",'DSA Problems'!H2:H251,"Solved") -> 0 | I16: =COUNTIFS('DSA Problems'!B2:B251,F16,'DSA Problems'!G2:G251,"NeetCode 150") -> 6 | J16: =COUNTIFS('DSA Problems'!B2:B251,F16,'DSA Problems'!H2:H251,"Solved") -> 0 | K16: =COUNTIF('DSA Problems'!B2:B251,F16) -> 10
F17: 1-D Dynamic Programming | G17: Week 6 | H17: =COUNTIFS('DSA Problems'!B2:B251,F17,'DSA Problems'!G2:G251,"NeetCode 150",'DSA Problems'!H2:H251,"Solved") -> 0 | I17: =COUNTIFS('DSA Problems'!B2:B251,F17,'DSA Problems'!G2:G251,"NeetCode 150") -> 12 | J17: =COUNTIFS('DSA Problems'!B2:B251,F17,'DSA Problems'!H2:H251,"Solved") -> 0 | K17: =COUNTIF('DSA Problems'!B2:B251,F17) -> 17
A18: Schedule (auto-adjusts for days off) | B18: Value | F18: 2-D Dynamic Programming | G18: Week 7 | H18: =COUNTIFS('DSA Problems'!B2:B251,F18,'DSA Problems'!G2:G251,"NeetCode 150",'DSA Problems'!H2:H251,"Solved") -> 0 | I18: =COUNTIFS('DSA Problems'!B2:B251,F18,'DSA Problems'!G2:G251,"NeetCode 150") -> 11 | J18: =COUNTIFS('DSA Problems'!B2:B251,F18,'DSA Problems'!H2:H251,"Solved") -> 0 | K18: =COUNTIF('DSA Problems'!B2:B251,F18) -> 16
A19: Days to Databricks DE exam (23 Oct) | B19: =MAX(0,DATE(2026,10,23)-TODAY()) -> 11 | F19: Greedy | G19: Week 7 | H19: =COUNTIFS('DSA Problems'!B2:B251,F19,'DSA Problems'!G2:G251,"NeetCode 150",'DSA Problems'!H2:H251,"Solved") -> 0 | I19: =COUNTIFS('DSA Problems'!B2:B251,F19,'DSA Problems'!G2:G251,"NeetCode 150") -> 8 | J19: =COUNTIFS('DSA Problems'!B2:B251,F19,'DSA Problems'!H2:H251,"Solved") -> 0 | K19: =COUNTIF('DSA Problems'!B2:B251,F19) -> 14
A20: Interview-ready date | B20: =INDEX('Daily Log'!$A$2:$A$93,MATCH(52,'Daily Log'!$D$2:$D$93,0)) -> 46357 | F20: Intervals | G20: Week 7 | H20: =COUNTIFS('DSA Problems'!B2:B251,F20,'DSA Problems'!G2:G251,"NeetCode 150",'DSA Problems'!H2:H251,"Solved") -> 0 | I20: =COUNTIFS('DSA Problems'!B2:B251,F20,'DSA Problems'!G2:G251,"NeetCode 150") -> 6 | J20: =COUNTIFS('DSA Problems'!B2:B251,F20,'DSA Problems'!H2:H251,"Solved") -> 0 | K20: =COUNTIF('DSA Problems'!B2:B251,F20) -> 7
A21: Days to interview-ready | B21: =MAX(0,INDEX('Daily Log'!$A$2:$A$93,MATCH(52,'Daily Log'!$D$2:$D$93,0))-TODAY()) -> 50 | F21: Math & Geometry | G21: Week 8 or stretch | H21: =COUNTIFS('DSA Problems'!B2:B251,F21,'DSA Problems'!G2:G251,"NeetCode 150",'DSA Problems'!H2:H251,"Solved") -> 0 | I21: =COUNTIFS('DSA Problems'!B2:B251,F21,'DSA Problems'!G2:G251,"NeetCode 150") -> 8 | J21: =COUNTIFS('DSA Problems'!B2:B251,F21,'DSA Problems'!H2:H251,"Solved") -> 0 | K21: =COUNTIF('DSA Problems'!B2:B251,F21) -> 13
A22: Plan finishes (end of week 8) | B22: =INDEX('Daily Log'!$A$2:$A$93,MATCH(57,'Daily Log'!$D$2:$D$93,0)) -> 46362 | F22: Bit Manipulation | G22: Week 8 or stretch | H22: =COUNTIFS('DSA Problems'!B2:B251,F22,'DSA Problems'!G2:G251,"NeetCode 150",'DSA Problems'!H2:H251,"Solved") -> 0 | I22: =COUNTIFS('DSA Problems'!B2:B251,F22,'DSA Problems'!G2:G251,"NeetCode 150") -> 7 | J22: =COUNTIFS('DSA Problems'!B2:B251,F22,'DSA Problems'!H2:H251,"Solved") -> 0 | K22: =COUNTIF('DSA Problems'!B2:B251,F22) -> 10
A23: Days off taken | B23: =COUNTIF('Daily Log'!C2:C93,"Yes") -> 0
A24: Current week of plan | B24: =IFERROR(INDEX('Daily Log'!E2:E93,MATCH(TODAY(),'Daily Log'!A2:A93,0)),0) -> 1
A25: Problems needed per day to hit 150 | B25: =IFERROR(ROUNDUP(MAX(0,150-B5)/MAX(1,INDEX('Daily Log'!$A$2:$A$93,MATCH(52,'Daily Log'!$D$2:$D$93,0))-TODAY()),1),0) -> 3
A27: How to use
A28: • Yellow cells are yours to fill in. Everything else is calculated.
A29: • Daily Log: pick Yes or No from the dropdown for each slot, and type problems solved and Gen AI hours (use 0.5 steps, e.g. 1.5). Today's row is highlighted.
A30: • Problems solved turns green at 3 or more (the daily target) and orange at 1–2.
A31: • Travelling or unable to study? In Daily Log, set Day off? to Yes for that date (you can mark future dates in advance). Weeks, checkpoints, milestones and your interview-ready date all shift forward automatically. The log runs to 10 Jan for spare days.
A32: • Grey cells marked — are not planned for that day (weekend routine).
A33: • Weekly Plan: weeks 1–3 are concept learning for HLD and LLD; full designs start in week 4.
A34: • Milestones: mark key dates and checkpoints done, and write one line per behavioral story.
A35: • DSA Problems: all 250 NeetCode problems, with the NeetCode 150 listed first in each topic. Set Status to Solved or Revisit; filter by List to see only the 150.
A36: • Targets: 150 problems is the core goal. The stretch row tracks progress toward 250.

Sheet Daily Log
A1: Date | B1: Day | C1: Day off? | D1: Study day | E1: Week | F1: Today's plan | G1: DSA morning | H1: System design | I1: Gen AI | J1: DSA night | K1: 10–11 pm slot | L1: Review | M1: Slots done | N1: Slots planned | O1: Problems solved (target 3) | P1: Gen AI hours | Q1: Mistakes log / notes
A2: 46306 | B2: Sun | D2: =IF(C2="Yes","",ROW()-1-COUNTIF($C$2:C2,"Yes")) -> 1 | E2: =IF(C2="Yes","",IF(D2>57,"Buffer",MIN(8,INT((D2-1)/7)+1))) -> 1 | F2: =IF(C2="Yes","Day off: the plan shifts forward one day",IF(D2>57,"Buffer: revision, weak topics, mock interviews",IF(D2=1,"Kickoff: two pointers basics + 2 easy problems · HLD intro (client-server, scaling) · Set up NeetCode list and notes",IF(WEEKDAY(A2,2)=6,"Contest or timed mock · "&IF(E2<=3,"Revise 2 HLD concepts","2 full HLD designs")&" · Deep dive (Kafka, hashing...) · Gen AI catch-up",IF(WEEKDAY(A2,2)=7,"Re-solve the week’s hardest · "&IF(E2<=3,"Revise LLD concepts","1 LLD design")&" · Read mistakes log · Half day off","DSA 10:10 · "&IF(MOD(WEEKDAY(A2,2),2)=1,"HLD","LLD")&IF(E2<=3," concepts"," design")&" 3:30 · Gen AI 5:30 · DSA 8:00 · "&IF(A2<DATE(2026,10,23),"DE practice exam",IF(A2=DATE(2026,10,23),"DATABRICKS EXAM DAY","Behavioral story + Gen AI hands-on"))&" · Review"))))) -> Kickoff: two pointers basics + 2 easy problems · HLD intro (client-server, scaling) · Set up NeetCode list and notes | I2: — | J2: — | K2: — | M2: =IF(C2="Yes",0,COUNTIF(G2:L2,"Yes")) -> 0 | N2: =IF(C2="Yes",0,6-COUNTIF(G2:L2,"—")) -> 3
A3: 46307 | B3: Mon | D3: =IF(C3="Yes","",ROW()-1-COUNTIF($C$2:C3,"Yes")) -> 2 | E3: =IF(C3="Yes","",IF(D3>57,"Buffer",MIN(8,INT((D3-1)/7)+1))) -> 1 | F3: =IF(C3="Yes","Day off: the plan shifts forward one day",IF(D3>57,"Buffer: revision, weak topics, mock interviews",IF(D3=1,"Kickoff: two pointers basics + 2 easy problems · HLD intro (client-server, scaling) · Set up NeetCode list and notes",IF(WEEKDAY(A3,2)=6,"Contest or timed mock · "&IF(E3<=3,"Revise 2 HLD concepts","2 full HLD designs")&" · Deep dive (Kafka, hashing...) · Gen AI catch-up",IF(WEEKDAY(A3,2)=7,"Re-solve the week’s hardest · "&IF(E3<=3,"Revise LLD concepts","1 LLD design")&" · Read mistakes log · Half day off","DSA 10:10 · "&IF(MOD(WEEKDAY(A3,2),2)=1,"HLD","LLD")&IF(E3<=3," concepts"," design")&" 3:30 · Gen AI 5:30 · DSA 8:00 · "&IF(A3<DATE(2026,10,23),"DE practice exam",IF(A3=DATE(2026,10,23),"DATABRICKS EXAM DAY","Behavioral story + Gen AI hands-on"))&" · Review"))))) -> DSA 10:10 · HLD concepts 3:30 · Gen AI 5:30 · DSA 8:00 · DE practice exam · Review | M3: =IF(C3="Yes",0,COUNTIF(G3:L3,"Yes")) -> 0 | N3: =IF(C3="Yes",0,6-COUNTIF(G3:L3,"—")) -> 6
A4: 46308 | B4: Tue | D4: =IF(C4="Yes","",ROW()-1-COUNTIF($C$2:C4,"Yes")) -> 3 | E4: =IF(C4="Yes","",IF(D4>57,"Buffer",MIN(8,INT((D4-1)/7)+1))) -> 1 | F4: =IF(C4="Yes","Day off: the plan shifts forward one day",IF(D4>57,"Buffer: revision, weak topics, mock interviews",IF(D4=1,"Kickoff: two pointers basics + 2 easy problems · HLD intro (client-server, scaling) · Set up NeetCode list and notes",IF(WEEKDAY(A4,2)=6,"Contest or timed mock · "&IF(E4<=3,"Revise 2 HLD concepts","2 full HLD designs")&" · Deep dive (Kafka, hashing...) · Gen AI catch-up",IF(WEEKDAY(A4,2)=7,"Re-solve the week’s hardest · "&IF(E4<=3,"Revise LLD concepts","1 LLD design")&" · Read mistakes log · Half day off","DSA 10:10 · "&IF(MOD(WEEKDAY(A4,2),2)=1,"HLD","LLD")&IF(E4<=3," concepts"," design")&" 3:30 · Gen AI 5:30 · DSA 8:00 · "&IF(A4<DATE(2026,10,23),"DE practice exam",IF(A4=DATE(2026,10,23),"DATABRICKS EXAM DAY","Behavioral story + Gen AI hands-on"))&" · Review"))))) -> DSA 10:10 · LLD concepts 3:30 · Gen AI 5:30 · DSA 8:00 · DE practice exam · Review | M4: =IF(C4="Yes",0,COUNTIF(G4:L4,"Yes")) -> 0 | N4: =IF(C4="Yes",0,6-COUNTIF(G4:L4,"—")) -> 6
A5: 46309 | B5: Wed | D5: =IF(C5="Yes","",ROW()-1-COUNTIF($C$2:C5,"Yes")) -> 4 | E5: =IF(C5="Yes","",IF(D5>57,"Buffer",MIN(8,INT((D5-1)/7)+1))) -> 1 | F5: =IF(C5="Yes","Day off: the plan shifts forward one day",IF(D5>57,"Buffer: revision, weak topics, mock interviews",IF(D5=1,"Kickoff: two pointers basics + 2 easy problems · HLD intro (client-server, scaling) · Set up NeetCode list and notes",IF(WEEKDAY(A5,2)=6,"Contest or timed mock · "&IF(E5<=3,"Revise 2 HLD concepts","2 full HLD designs")&" · Deep dive (Kafka, hashing...) · Gen AI catch-up",IF(WEEKDAY(A5,2)=7,"Re-solve the week’s hardest · "&IF(E5<=3,"Revise LLD concepts","1 LLD design")&" · Read mistakes log · Half day off","DSA 10:10 · "&IF(MOD(WEEKDAY(A5,2),2)=1,"HLD","LLD")&IF(E5<=3," concepts"," design")&" 3:30 · Gen AI 5:30 · DSA 8:00 · "&IF(A5<DATE(2026,10,23),"DE practice exam",IF(A5=DATE(2026,10,23),"DATABRICKS EXAM DAY","Behavioral story + Gen AI hands-on"))&" · Review"))))) -> DSA 10:10 · HLD concepts 3:30 · Gen AI 5:30 · DSA 8:00 · DE practice exam · Review | M5: =IF(C5="Yes",0,COUNTIF(G5:L5,"Yes")) -> 0 | N5: =IF(C5="Yes",0,6-COUNTIF(G5:L5,"—")) -> 6
A6: 46310 | B6: Thu | D6: =IF(C6="Yes","",ROW()-1-COUNTIF($C$2:C6,"Yes")) -> 5 | E6: =IF(C6="Yes","",IF(D6>57,"Buffer",MIN(8,INT((D6-1)/7)+1))) -> 1 | F6: =IF(C6="Yes","Day off: the plan shifts forward one day",IF(D6>57,"Buffer: revision, weak topics, mock interviews",IF(D6=1,"Kickoff: two pointers basics + 2 easy problems · HLD intro (client-server, scaling) · Set up NeetCode list and notes",IF(WEEKDAY(A6,2)=6,"Contest or timed mock · "&IF(E6<=3,"Revise 2 HLD concepts","2 full HLD designs")&" · Deep dive (Kafka, hashing...) · Gen AI catch-up",IF(WEEKDAY(A6,2)=7,"Re-solve the week’s hardest · "&IF(E6<=3,"Revise LLD concepts","1 LLD design")&" · Read mistakes log · Half day off","DSA 10:10 · "&IF(MOD(WEEKDAY(A6,2),2)=1,"HLD","LLD")&IF(E6<=3," concepts"," design")&" 3:30 · Gen AI 5:30 · DSA 8:00 · "&IF(A6<DATE(2026,10,23),"DE practice exam",IF(A6=DATE(2026,10,23),"DATABRICKS EXAM DAY","Behavioral story + Gen AI hands-on"))&" · Review"))))) -> DSA 10:10 · LLD concepts 3:30 · Gen AI 5:30 · DSA 8:00 · DE practice exam · Review | M6: =IF(C6="Yes",0,COUNTIF(G6:L6,"Yes")) -> 0 | N6: =IF(C6="Yes",0,6-COUNTIF(G6:L6,"—")) -> 6
A7: 46311 | B7: Fri | D7: =IF(C7="Yes","",ROW()-1-COUNTIF($C$2:C7,"Yes")) -> 6 | E7: =IF(C7="Yes","",IF(D7>57,"Buffer",MIN(8,INT((D7-1)/7)+1))) -> 1 | F7: =IF(C7="Yes","Day off: the plan shifts forward one day",IF(D7>57,"Buffer: revision, weak topics, mock interviews",IF(D7=1,"Kickoff: two pointers basics + 2 easy problems · HLD intro (client-server, scaling) · Set up NeetCode list and notes",IF(WEEKDAY(A7,2)=6,"Contest or timed mock · "&IF(E7<=3,"Revise 2 HLD concepts","2 full HLD designs")&" · Deep dive (Kafka, hashing...) · Gen AI catch-up",IF(WEEKDAY(A7,2)=7,"Re-solve the week’s hardest · "&IF(E7<=3,"Revise LLD concepts","1 LLD design")&" · Read mistakes log · Half day off","DSA 10:10 · "&IF(MOD(WEEKDAY(A7,2),2)=1,"HLD","LLD")&IF(E7<=3," concepts"," design")&" 3:30 · Gen AI 5:30 · DSA 8:00 · "&IF(A7<DATE(2026,10,23),"DE practice exam",IF(A7=DATE(2026,10,23),"DATABRICKS EXAM DAY","Behavioral story + Gen AI hands-on"))&" · Review"))))) -> DSA 10:10 · HLD concepts 3:30 · Gen AI 5:30 · DSA 8:00 · DE practice exam · Review | M7: =IF(C7="Yes",0,COUNTIF(G7:L7,"Yes")) -> 0 | N7: =IF(C7="Yes",0,6-COUNTIF(G7:L7,"—")) -> 6
A8: 46312 | B8: Sat | D8: =IF(C8="Yes","",ROW()-1-COUNTIF($C$2:C8,"Yes")) -> 7 | E8: =IF(C8="Yes","",IF(D8>57,"Buffer",MIN(8,INT((D8-1)/7)+1))) -> 1 | F8: =IF(C8="Yes","Day off: the plan shifts forward one day",IF(D8>57,"Buffer: revision, weak topics, mock interviews",IF(D8=1,"Kickoff: two pointers basics + 2 easy problems · HLD intro (client-server, scaling) · Set up NeetCode list and notes",IF(WEEKDAY(A8,2)=6,"Contest or timed mock · "&IF(E8<=3,"Revise 2 HLD concepts","2 full HLD designs")&" · Deep dive (Kafka, hashing...) · Gen AI catch-up",IF(WEEKDAY(A8,2)=7,"Re-solve the week’s hardest · "&IF(E8<=3,"Revise LLD concepts","1 LLD design")&" · Read mistakes log · Half day off","DSA 10:10 · "&IF(MOD(WEEKDAY(A8,2),2)=1,"HLD","LLD")&IF(E8<=3," concepts"," design")&" 3:30 · Gen AI 5:30 · DSA 8:00 · "&IF(A8<DATE(2026,10,23),"DE practice exam",IF(A8=DATE(2026,10,23),"DATABRICKS EXAM DAY","Behavioral story + Gen AI hands-on"))&" · Review"))))) -> Contest or timed mock · Revise 2 HLD concepts · Deep dive (Kafka, hashing...) · Gen AI catch-up | J8: — | L8: — | M8: =IF(C8="Yes",0,COUNTIF(G8:L8,"Yes")) -> 0 | N8: =IF(C8="Yes",0,6-COUNTIF(G8:L8,"—")) -> 4
A9: 46313 | B9: Sun | D9: =IF(C9="Yes","",ROW()-1-COUNTIF($C$2:C9,"Yes")) -> 8 | E9: =IF(C9="Yes","",IF(D9>57,"Buffer",MIN(8,INT((D9-1)/7)+1))) -> 2 | F9: =IF(C9="Yes","Day off: the plan shifts forward one day",IF(D9>57,"Buffer: revision, weak topics, mock interviews",IF(D9=1,"Kickoff: two pointers basics + 2 easy problems · HLD intro (client-server, scaling) · Set up NeetCode list and notes",IF(WEEKDAY(A9,2)=6,"Contest or timed mock · "&IF(E9<=3,"Revise 2 HLD concepts","2 full HLD designs")&" · Deep dive (Kafka, hashing...) · Gen AI catch-up",IF(WEEKDAY(A9,2)=7,"Re-solve the week’s hardest · "&IF(E9<=3,"Revise LLD concepts","1 LLD design")&" · Read mistakes log · Half day off","DSA 10:10 · "&IF(MOD(WEEKDAY(A9,2),2)=1,"HLD","LLD")&IF(E9<=3," concepts"," design")&" 3:30 · Gen AI 5:30 · DSA 8:00 · "&IF(A9<DATE(2026,10,23),"DE practice exam",IF(A9=DATE(2026,10,23),"DATABRICKS EXAM DAY","Behavioral story + Gen AI hands-on"))&" · Review"))))) -> Re-solve the week’s hardest · Revise LLD concepts · Read mistakes log · Half day off | I9: — | J9: — | K9: — | M9: =IF(C9="Yes",0,COUNTIF(G9:L9,"Yes")) -> 0 | N9: =IF(C9="Yes",0,6-COUNTIF(G9:L9,"—")) -> 3
A10: 46314 | B10: Mon | D10: =IF(C10="Yes","",ROW()-1-COUNTIF($C$2:C10,"Yes")) -> 9 | E10: =IF(C10="Yes","",IF(D10>57,"Buffer",MIN(8,INT((D10-1)/7)+1))) -> 2 | F10: =IF(C10="Yes","Day off: the plan shifts forward one day",IF(D10>57,"Buffer: revision, weak topics, mock interviews",IF(D10=1,"Kickoff: two pointers basics + 2 easy problems · HLD intro (client-server, scaling) · Set up NeetCode list and notes",IF(WEEKDAY(A10,2)=6,"Contest or timed mock · "&IF(E10<=3,"Revise 2 HLD concepts","2 full HLD designs")&" · Deep dive (Kafka, hashing...) · Gen AI catch-up",IF(WEEKDAY(A10,2)=7,"Re-solve the week’s hardest · "&IF(E10<=3,"Revise LLD concepts","1 LLD design")&" · Read mistakes log · Half day off","DSA 10:10 · "&IF(MOD(WEEKDAY(A10,2),2)=1,"HLD","LLD")&IF(E10<=3," concepts"," design")&" 3:30 · Gen AI 5:30 · DSA 8:00 · "&IF(A10<DATE(2026,10,23),"DE practice exam",IF(A10=DATE(2026,10,23),"DATABRICKS EXAM DAY","Behavioral story + Gen AI hands-on"))&" · Review"))))) -> DSA 10:10 · HLD concepts 3:30 · Gen AI 5:30 · DSA 8:00 · DE practice exam · Review | M10: =IF(C10="Yes",0,COUNTIF(G10:L10,"Yes")) -> 0 | N10: =IF(C10="Yes",0,6-COUNTIF(G10:L10,"—")) -> 6
A11: 46315 | B11: Tue | D11: =IF(C11="Yes","",ROW()-1-COUNTIF($C$2:C11,"Yes")) -> 10 | E11: =IF(C11="Yes","",IF(D11>57,"Buffer",MIN(8,INT((D11-1)/7)+1))) -> 2 | F11: =IF(C11="Yes","Day off: the plan shifts forward one day",IF(D11>57,"Buffer: revision, weak topics, mock interviews",IF(D11=1,"Kickoff: two pointers basics + 2 easy problems · HLD intro (client-server, scaling) · Set up NeetCode list and notes",IF(WEEKDAY(A11,2)=6,"Contest or timed mock · "&IF(E11<=3,"Revise 2 HLD concepts","2 full HLD designs")&" · Deep dive (Kafka, hashing...) · Gen AI catch-up",IF(WEEKDAY(A11,2)=7,"Re-solve the week’s hardest · "&IF(E11<=3,"Revise LLD concepts","1 LLD design")&" · Read mistakes log · Half day off","DSA 10:10 · "&IF(MOD(WEEKDAY(A11,2),2)=1,"HLD","LLD")&IF(E11<=3," concepts"," design")&" 3:30 · Gen AI 5:30 · DSA 8:00 · "&IF(A11<DATE(2026,10,23),"DE practice exam",IF(A11=DATE(2026,10,23),"DATABRICKS EXAM DAY","Behavioral story + Gen AI hands-on"))&" · Review"))))) -> DSA 10:10 · LLD concepts 3:30 · Gen AI 5:30 · DSA 8:00 · DE practice exam · Review | M11: =IF(C11="Yes",0,COUNTIF(G11:L11,"Yes")) -> 0 | N11: =IF(C11="Yes",0,6-COUNTIF(G11:L11,"—")) -> 6
A12: 46316 | B12: Wed | D12: =IF(C12="Yes","",ROW()-1-COUNTIF($C$2:C12,"Yes")) -> 11 | E12: =IF(C12="Yes","",IF(D12>57,"Buffer",MIN(8,INT((D12-1)/7)+1))) -> 2 | F12: =IF(C12="Yes","Day off: the plan shifts forward one day",IF(D12>57,"Buffer: revision, weak topics, mock interviews",IF(D12=1,"Kickoff: two pointers basics + 2 easy problems · HLD intro (client-server, scaling) · Set up NeetCode list and notes",IF(WEEKDAY(A12,2)=6,"Contest or timed mock · "&IF(E12<=3,"Revise 2 HLD concepts","2 full HLD designs")&" · Deep dive (Kafka, hashing...) · Gen AI catch-up",IF(WEEKDAY(A12,2)=7,"Re-solve the week’s hardest · "&IF(E12<=3,"Revise LLD concepts","1 LLD design")&" · Read mistakes log · Half day off","DSA 10:10 · "&IF(MOD(WEEKDAY(A12,2),2)=1,"HLD","LLD")&IF(E12<=3," concepts"," design")&" 3:30 · Gen AI 5:30 · DSA 8:00 · "&IF(A12<DATE(2026,10,23),"DE practice exam",IF(A12=DATE(2026,10,23),"DATABRICKS EXAM DAY","Behavioral story + Gen AI hands-on"))&" · Review"))))) -> DSA 10:10 · HLD concepts 3:30 · Gen AI 5:30 · DSA 8:00 · DE practice exam · Review | M12: =IF(C12="Yes",0,COUNTIF(G12:L12,"Yes")) -> 0 | N12: =IF(C12="Yes",0,6-COUNTIF(G12:L12,"—")) -> 6
A13: 46317 | B13: Thu | D13: =IF(C13="Yes","",ROW()-1-COUNTIF($C$2:C13,"Yes")) -> 12 | E13: =IF(C13="Yes","",IF(D13>57,"Buffer",MIN(8,INT((D13-1)/7)+1))) -> 2 | F13: =IF(C13="Yes","Day off: the plan shifts forward one day",IF(D13>57,"Buffer: revision, weak topics, mock interviews",IF(D13=1,"Kickoff: two pointers basics + 2 easy problems · HLD intro (client-server, scaling) · Set up NeetCode list and notes",IF(WEEKDAY(A13,2)=6,"Contest or timed mock · "&IF(E13<=3,"Revise 2 HLD concepts","2 full HLD designs")&" · Deep dive (Kafka, hashing...) · Gen AI catch-up",IF(WEEKDAY(A13,2)=7,"Re-solve the week’s hardest · "&IF(E13<=3,"Revise LLD concepts","1 LLD design")&" · Read mistakes log · Half day off","DSA 10:10 · "&IF(MOD(WEEKDAY(A13,2),2)=1,"HLD","LLD")&IF(E13<=3," concepts"," design")&" 3:30 · Gen AI 5:30 · DSA 8:00 · "&IF(A13<DATE(2026,10,23),"DE practice exam",IF(A13=DATE(2026,10,23),"DATABRICKS EXAM DAY","Behavioral story + Gen AI hands-on"))&" · Review"))))) -> DSA 10:10 · LLD concepts 3:30 · Gen AI 5:30 · DSA 8:00 · DE practice exam · Review | M13: =IF(C13="Yes",0,COUNTIF(G13:L13,"Yes")) -> 0 | N13: =IF(C13="Yes",0,6-COUNTIF(G13:L13,"—")) -> 6
A14: 46318 | B14: Fri | D14: =IF(C14="Yes","",ROW()-1-COUNTIF($C$2:C14,"Yes")) -> 13 | E14: =IF(C14="Yes","",IF(D14>57,"Buffer",MIN(8,INT((D14-1)/7)+1))) -> 2 | F14: =IF(C14="Yes","Day off: the plan shifts forward one day",IF(D14>57,"Buffer: revision, weak topics, mock interviews",IF(D14=1,"Kickoff: two pointers basics + 2 easy problems · HLD intro (client-server, scaling) · Set up NeetCode list and notes",IF(WEEKDAY(A14,2)=6,"Contest or timed mock · "&IF(E14<=3,"Revise 2 HLD concepts","2 full HLD designs")&" · Deep dive (Kafka, hashing...) · Gen AI catch-up",IF(WEEKDAY(A14,2)=7,"Re-solve the week’s hardest · "&IF(E14<=3,"Revise LLD concepts","1 LLD design")&" · Read mistakes log · Half day off","DSA 10:10 · "&IF(MOD(WEEKDAY(A14,2),2)=1,"HLD","LLD")&IF(E14<=3," concepts"," design")&" 3:30 · Gen AI 5:30 · DSA 8:00 · "&IF(A14<DATE(2026,10,23),"DE practice exam",IF(A14=DATE(2026,10,23),"DATABRICKS EXAM DAY","Behavioral story + Gen AI hands-on"))&" · Review"))))) -> DSA 10:10 · HLD concepts 3:30 · Gen AI 5:30 · DSA 8:00 · DATABRICKS EXAM DAY · Review | M14: =IF(C14="Yes",0,COUNTIF(G14:L14,"Yes")) -> 0 | N14: =IF(C14="Yes",0,6-COUNTIF(G14:L14,"—")) -> 6
A15: 46319 | B15: Sat | D15: =IF(C15="Yes","",ROW()-1-COUNTIF($C$2:C15,"Yes")) -> 14 | E15: =IF(C15="Yes","",IF(D15>57,"Buffer",MIN(8,INT((D15-1)/7)+1))) -> 2 | F15: =IF(C15="Yes","Day off: the plan shifts forward one day",IF(D15>57,"Buffer: revision, weak topics, mock interviews",IF(D15=1,"Kickoff: two pointers basics + 2 easy problems · HLD intro (client-server, scaling) · Set up NeetCode list and notes",IF(WEEKDAY(A15,2)=6,"Contest or timed mock · "&IF(E15<=3,"Revise 2 HLD concepts","2 full HLD designs")&" · Deep dive (Kafka, hashing...) · Gen AI catch-up",IF(WEEKDAY(A15,2)=7,"Re-solve the week’s hardest · "&IF(E15<=3,"Revise LLD concepts","1 LLD design")&" · Read mistakes log · Half day off","DSA 10:10 · "&IF(MOD(WEEKDAY(A15,2),2)=1,"HLD","LLD")&IF(E15<=3," concepts"," design")&" 3:30 · Gen AI 5:30 · DSA 8:00 · "&IF(A15<DATE(2026,10,23),"DE practice exam",IF(A15=DATE(2026,10,23),"DATABRICKS EXAM DAY","Behavioral story + Gen AI hands-on"))&" · Review"))))) -> Contest or timed mock · Revise 2 HLD concepts · Deep dive (Kafka, hashing...) · Gen AI catch-up | J15: — | L15: — | M15: =IF(C15="Yes",0,COUNTIF(G15:L15,"Yes")) -> 0 | N15: =IF(C15="Yes",0,6-COUNTIF(G15:L15,"—")) -> 4
A16: 46320 | B16: Sun | D16: =IF(C16="Yes","",ROW()-1-COUNTIF($C$2:C16,"Yes")) -> 15 | E16: =IF(C16="Yes","",IF(D16>57,"Buffer",MIN(8,INT((D16-1)/7)+1))) -> 3 | F16: =IF(C16="Yes","Day off: the plan shifts forward one day",IF(D16>57,"Buffer: revision, weak topics, mock interviews",IF(D16=1,"Kickoff: two pointers basics + 2 easy problems · HLD intro (client-server, scaling) · Set up NeetCode list and notes",IF(WEEKDAY(A16,2)=6,"Contest or timed mock · "&IF(E16<=3,"Revise 2 HLD concepts","2 full HLD designs")&" · Deep dive (Kafka, hashing...) · Gen AI catch-up",IF(WEEKDAY(A16,2)=7,"Re-solve the week’s hardest · "&IF(E16<=3,"Revise LLD concepts","1 LLD design")&" · Read mistakes log · Half day off","DSA 10:10 · "&IF(MOD(WEEKDAY(A16,2),2)=1,"HLD","LLD")&IF(E16<=3," concepts"," design")&" 3:30 · Gen AI 5:30 · DSA 8:00 · "&IF(A16<DATE(2026,10,23),"DE practice exam",IF(A16=DATE(2026,10,23),"DATABRICKS EXAM DAY","Behavioral story + Gen AI hands-on"))&" · Review"))))) -> Re-solve the week’s hardest · Revise LLD concepts · Read mistakes log · Half day off | I16: — | J16: — | K16: — | M16: =IF(C16="Yes",0,COUNTIF(G16:L16,"Yes")) -> 0 | N16: =IF(C16="Yes",0,6-COUNTIF(G16:L16,"—")) -> 3
A17: 46321 | B17: Mon | D17: =IF(C17="Yes","",ROW()-1-COUNTIF($C$2:C17,"Yes")) -> 16 | E17: =IF(C17="Yes","",IF(D17>57,"Buffer",MIN(8,INT((D17-1)/7)+1))) -> 3 | F17: =IF(C17="Yes","Day off: the plan shifts forward one day",IF(D17>57,"Buffer: revision, weak topics, mock interviews",IF(D17=1,"Kickoff: two pointers basics + 2 easy problems · HLD intro (client-server, scaling) · Set up NeetCode list and notes",IF(WEEKDAY(A17,2)=6,"Contest or timed mock · "&IF(E17<=3,"Revise 2 HLD concepts","2 full HLD designs")&" · Deep dive (Kafka, hashing...) · Gen AI catch-up",IF(WEEKDAY(A17,2)=7,"Re-solve the week’s hardest · "&IF(E17<=3,"Revise LLD concepts","1 LLD design")&" · Read mistakes log · Half day off","DSA 10:10 · "&IF(MOD(WEEKDAY(A17,2),2)=1,"HLD","LLD")&IF(E17<=3," concepts"," design")&" 3:30 · Gen AI 5:30 · DSA 8:00 · "&IF(A17<DATE(2026,10,23),"DE practice exam",IF(A17=DATE(2026,10,23),"DATABRICKS EXAM DAY","Behavioral story + Gen AI hands-on"))&" · Review"))))) -> DSA 10:10 · HLD concepts 3:30 · Gen AI 5:30 · DSA 8:00 · Behavioral story + Gen AI hands-on · Review | M17: =IF(C17="Yes",0,COUNTIF(G17:L17,"Yes")) -> 0 | N17: =IF(C17="Yes",0,6-COUNTIF(G17:L17,"—")) -> 6
A18: 46322 | B18: Tue | D18: =IF(C18="Yes","",ROW()-1-COUNTIF($C$2:C18,"Yes")) -> 17 | E18: =IF(C18="Yes","",IF(D18>57,"Buffer",MIN(8,INT((D18-1)/7)+1))) -> 3 | F18: =IF(C18="Yes","Day off: the plan shifts forward one day",IF(D18>57,"Buffer: revision, weak topics, mock interviews",IF(D18=1,"Kickoff: two pointers basics + 2 easy problems · HLD intro (client-server, scaling) · Set up NeetCode list and notes",IF(WEEKDAY(A18,2)=6,"Contest or timed mock · "&IF(E18<=3,"Revise 2 HLD concepts","2 full HLD designs")&" · Deep dive (Kafka, hashing...) · Gen AI catch-up",IF(WEEKDAY(A18,2)=7,"Re-solve the week’s hardest · "&IF(E18<=3,"Revise LLD concepts","1 LLD design")&" · Read mistakes log · Half day off","DSA 10:10 · "&IF(MOD(WEEKDAY(A18,2),2)=1,"HLD","LLD")&IF(E18<=3," concepts"," design")&" 3:30 · Gen AI 5:30 · DSA 8:00 · "&IF(A18<DATE(2026,10,23),"DE practice exam",IF(A18=DATE(2026,10,23),"DATABRICKS EXAM DAY","Behavioral story + Gen AI hands-on"))&" · Review"))))) -> DSA 10:10 · LLD concepts 3:30 · Gen AI 5:30 · DSA 8:00 · Behavioral story + Gen AI hands-on · Review | M18: =IF(C18="Yes",0,COUNTIF(G18:L18,"Yes")) -> 0 | N18: =IF(C18="Yes",0,6-COUNTIF(G18:L18,"—")) -> 6
A19: 46323 | B19: Wed | D19: =IF(C19="Yes","",ROW()-1-COUNTIF($C$2:C19,"Yes")) -> 18 | E19: =IF(C19="Yes","",IF(D19>57,"Buffer",MIN(8,INT((D19-1)/7)+1))) -> 3 | F19: =IF(C19="Yes","Day off: the plan shifts forward one day",IF(D19>57,"Buffer: revision, weak topics, mock interviews",IF(D19=1,"Kickoff: two pointers basics + 2 easy problems · HLD intro (client-server, scaling) · Set up NeetCode list and notes",IF(WEEKDAY(A19,2)=6,"Contest or timed mock · "&IF(E19<=3,"Revise 2 HLD concepts","2 full HLD designs")&" · Deep dive (Kafka, hashing...) · Gen AI catch-up",IF(WEEKDAY(A19,2)=7,"Re-solve the week’s hardest · "&IF(E19<=3,"Revise LLD concepts","1 LLD design")&" · Read mistakes log · Half day off","DSA 10:10 · "&IF(MOD(WEEKDAY(A19,2),2)=1,"HLD","LLD")&IF(E19<=3," concepts"," design")&" 3:30 · Gen AI 5:30 · DSA 8:00 · "&IF(A19<DATE(2026,10,23),"DE practice exam",IF(A19=DATE(2026,10,23),"DATABRICKS EXAM DAY","Behavioral story + Gen AI hands-on"))&" · Review"))))) -> DSA 10:10 · HLD concepts 3:30 · Gen AI 5:30 · DSA 8:00 · Behavioral story + Gen AI hands-on · Review | M19: =IF(C19="Yes",0,COUNTIF(G19:L19,"Yes")) -> 0 | N19: =IF(C19="Yes",0,6-COUNTIF(G19:L19,"—")) -> 6
A20: 46324 | B20: Thu | D20: =IF(C20="Yes","",ROW()-1-COUNTIF($C$2:C20,"Yes")) -> 19 | E20: =IF(C20="Yes","",IF(D20>57,"Buffer",MIN(8,INT((D20-1)/7)+1))) -> 3 | F20: =IF(C20="Yes","Day off: the plan shifts forward one day",IF(D20>57,"Buffer: revision, weak topics, mock interviews",IF(D20=1,"Kickoff: two pointers basics + 2 easy problems · HLD intro (client-server, scaling) · Set up NeetCode list and notes",IF(WEEKDAY(A20,2)=6,"Contest or timed mock · "&IF(E20<=3,"Revise 2 HLD concepts","2 full HLD designs")&" · Deep dive (Kafka, hashing...) · Gen AI catch-up",IF(WEEKDAY(A20,2)=7,"Re-solve the week’s hardest · "&IF(E20<=3,"Revise LLD concepts","1 LLD design")&" · Read mistakes log · Half day off","DSA 10:10 · "&IF(MOD(WEEKDAY(A20,2),2)=1,"HLD","LLD")&IF(E20<=3," concepts"," design")&" 3:30 · Gen AI 5:30 · DSA 8:00 · "&IF(A20<DATE(2026,10,23),"DE practice exam",IF(A20=DATE(2026,10,23),"DATABRICKS EXAM DAY","Behavioral story + Gen AI hands-on"))&" · Review"))))) -> DSA 10:10 · LLD concepts 3:30 · Gen AI 5:30 · DSA 8:00 · Behavioral story + Gen AI hands-on · Review | M20: =IF(C20="Yes",0,COUNTIF(G20:L20,"Yes")) -> 0 | N20: =IF(C20="Yes",0,6-COUNTIF(G20:L20,"—")) -> 6
A21: 46325 | B21: Fri | D21: =IF(C21="Yes","",ROW()-1-COUNTIF($C$2:C21,"Yes")) -> 20 | E21: =IF(C21="Yes","",IF(D21>57,"Buffer",MIN(8,INT((D21-1)/7)+1))) -> 3 | F21: =IF(C21="Yes","Day off: the plan shifts forward one day",IF(D21>57,"Buffer: revision, weak topics, mock interviews",IF(D21=1,"Kickoff: two pointers basics + 2 easy problems · HLD intro (client-server, scaling) · Set up NeetCode list and notes",IF(WEEKDAY(A21,2)=6,"Contest or timed mock · "&IF(E21<=3,"Revise 2 HLD concepts","2 full HLD designs")&" · Deep dive (Kafka, hashing...) · Gen AI catch-up",IF(WEEKDAY(A21,2)=7,"Re-solve the week’s hardest · "&IF(E21<=3,"Revise LLD concepts","1 LLD design")&" · Read mistakes log · Half day off","DSA 10:10 · "&IF(MOD(WEEKDAY(A21,2),2)=1,"HLD","LLD")&IF(E21<=3," concepts"," design")&" 3:30 · Gen AI 5:30 · DSA 8:00 · "&IF(A21<DATE(2026,10,23),"DE practice exam",IF(A21=DATE(2026,10,23),"DATABRICKS EXAM DAY","Behavioral story + Gen AI hands-on"))&" · Review"))))) -> DSA 10:10 · HLD concepts 3:30 · Gen AI 5:30 · DSA 8:00 · Behavioral story + Gen AI hands-on · Review | M21: =IF(C21="Yes",0,COUNTIF(G21:L21,"Yes")) -> 0 | N21: =IF(C21="Yes",0,6-COUNTIF(G21:L21,"—")) -> 6
A22: 46326 | B22: Sat | D22: =IF(C22="Yes","",ROW()-1-COUNTIF($C$2:C22,"Yes")) -> 21 | E22: =IF(C22="Yes","",IF(D22>57,"Buffer",MIN(8,INT((D22-1)/7)+1))) -> 3 | F22: =IF(C22="Yes","Day off: the plan shifts forward one day",IF(D22>57,"Buffer: revision, weak topics, mock interviews",IF(D22=1,"Kickoff: two pointers basics + 2 easy problems · HLD intro (client-server, scaling) · Set up NeetCode list and notes",IF(WEEKDAY(A22,2)=6,"Contest or timed mock · "&IF(E22<=3,"Revise 2 HLD concepts","2 full HLD designs")&" · Deep dive (Kafka, hashing...) · Gen AI catch-up",IF(WEEKDAY(A22,2)=7,"Re-solve the week’s hardest · "&IF(E22<=3,"Revise LLD concepts","1 LLD design")&" · Read mistakes log · Half day off","DSA 10:10 · "&IF(MOD(WEEKDAY(A22,2),2)=1,"HLD","LLD")&IF(E22<=3," concepts"," design")&" 3:30 · Gen AI 5:30 · DSA 8:00 · "&IF(A22<DATE(2026,10,23),"DE practice exam",IF(A22=DATE(2026,10,23),"DATABRICKS EXAM DAY","Behavioral story + Gen AI hands-on"))&" · Review"))))) -> Contest or timed mock · Revise 2 HLD concepts · Deep dive (Kafka, hashing...) · Gen AI catch-up | J22: — | L22: — | M22: =IF(C22="Yes",0,COUNTIF(G22:L22,"Yes")) -> 0 | N22: =IF(C22="Yes",0,6-COUNTIF(G22:L22,"—")) -> 4
A23: 46327 | B23: Sun | D23: =IF(C23="Yes","",ROW()-1-COUNTIF($C$2:C23,"Yes")) -> 22 | E23: =IF(C23="Yes","",IF(D23>57,"Buffer",MIN(8,INT((D23-1)/7)+1))) -> 4 | F23: =IF(C23="Yes","Day off: the plan shifts forward one day",IF(D23>57,"Buffer: revision, weak topics, mock interviews",IF(D23=1,"Kickoff: two pointers basics + 2 easy problems · HLD intro (client-server, scaling) · Set up NeetCode list and notes",IF(WEEKDAY(A23,2)=6,"Contest or timed mock · "&IF(E23<=3,"Revise 2 HLD concepts","2 full HLD designs")&" · Deep dive (Kafka, hashing...) · Gen AI catch-up",IF(WEEKDAY(A23,2)=7,"Re-solve the week’s hardest · "&IF(E23<=3,"Revise LLD concepts","1 LLD design")&" · Read mistakes log · Half day off","DSA 10:10 · "&IF(MOD(WEEKDAY(A23,2),2)=1,"HLD","LLD")&IF(E23<=3," concepts"," design")&" 3:30 · Gen AI 5:30 · DSA 8:00 · "&IF(A23<DATE(2026,10,23),"DE practice exam",IF(A23=DATE(2026,10,23),"DATABRICKS EXAM DAY","Behavioral story + Gen AI hands-on"))&" · Review"))))) -> Re-solve the week’s hardest · 1 LLD design · Read mistakes log · Half day off | I23: — | J23: — | K23: — | M23: =IF(C23="Yes",0,COUNTIF(G23:L23,"Yes")) -> 0 | N23: =IF(C23="Yes",0,6-COUNTIF(G23:L23,"—")) -> 3
A24: 46328 | B24: Mon | D24: =IF(C24="Yes","",ROW()-1-COUNTIF($C$2:C24,"Yes")) -> 23 | E24: =IF(C24="Yes","",IF(D24>57,"Buffer",MIN(8,INT((D24-1)/7)+1))) -> 4 | F24: =IF(C24="Yes","Day off: the plan shifts forward one day",IF(D24>57,"Buffer: revision, weak topics, mock interviews",IF(D24=1,"Kickoff: two pointers basics + 2 easy problems · HLD intro (client-server, scaling) · Set up NeetCode list and notes",IF(WEEKDAY(A24,2)=6,"Contest or timed mock · "&IF(E24<=3,"Revise 2 HLD concepts","2 full HLD designs")&" · Deep dive (Kafka, hashing...) · Gen AI catch-up",IF(WEEKDAY(A24,2)=7,"Re-solve the week’s hardest · "&IF(E24<=3,"Revise LLD concepts","1 LLD design")&" · Read mistakes log · Half day off","DSA 10:10 · "&IF(MOD(WEEKDAY(A24,2),2)=1,"HLD","LLD")&IF(E24<=3," concepts"," design")&" 3:30 · Gen AI 5:30 · DSA 8:00 · "&IF(A24<DATE(2026,10,23),"DE practice exam",IF(A24=DATE(2026,10,23),"DATABRICKS EXAM DAY","Behavioral story + Gen AI hands-on"))&" · Review"))))) -> DSA 10:10 · HLD design 3:30 · Gen AI 5:30 · DSA 8:00 · Behavioral story + Gen AI hands-on · Review | M24: =IF(C24="Yes",0,COUNTIF(G24:L24,"Yes")) -> 0 | N24: =IF(C24="Yes",0,6-COUNTIF(G24:L24,"—")) -> 6
A25: 46329 | B25: Tue | D25: =IF(C25="Yes","",ROW()-1-COUNTIF($C$2:C25,"Yes")) -> 24 | E25: =IF(C25="Yes","",IF(D25>57,"Buffer",MIN(8,INT((D25-1)/7)+1))) -> 4 | F25: =IF(C25="Yes","Day off: the plan shifts forward one day",IF(D25>57,"Buffer: revision, weak topics, mock interviews",IF(D25=1,"Kickoff: two pointers basics + 2 easy problems · HLD intro (client-server, scaling) · Set up NeetCode list and notes",IF(WEEKDAY(A25,2)=6,"Contest or timed mock · "&IF(E25<=3,"Revise 2 HLD concepts","2 full HLD designs")&" · Deep dive (Kafka, hashing...) · Gen AI catch-up",IF(WEEKDAY(A25,2)=7,"Re-solve the week’s hardest · "&IF(E25<=3,"Revise LLD concepts","1 LLD design")&" · Read mistakes log · Half day off","DSA 10:10 · "&IF(MOD(WEEKDAY(A25,2),2)=1,"HLD","LLD")&IF(E25<=3," concepts"," design")&" 3:30 · Gen AI 5:30 · DSA 8:00 · "&IF(A25<DATE(2026,10,23),"DE practice exam",IF(A25=DATE(2026,10,23),"DATABRICKS EXAM DAY","Behavioral story + Gen AI hands-on"))&" · Review"))))) -> DSA 10:10 · LLD design 3:30 · Gen AI 5:30 · DSA 8:00 · Behavioral story + Gen AI hands-on · Review | M25: =IF(C25="Yes",0,COUNTIF(G25:L25,"Yes")) -> 0 | N25: =IF(C25="Yes",0,6-COUNTIF(G25:L25,"—")) -> 6
A26: 46330 | B26: Wed | D26: =IF(C26="Yes","",ROW()-1-COUNTIF($C$2:C26,"Yes")) -> 25 | E26: =IF(C26="Yes","",IF(D26>57,"Buffer",MIN(8,INT((D26-1)/7)+1))) -> 4 | F26: =IF(C26="Yes","Day off: the plan shifts forward one day",IF(D26>57,"Buffer: revision, weak topics, mock interviews",IF(D26=1,"Kickoff: two pointers basics + 2 easy problems · HLD intro (client-server, scaling) · Set up NeetCode list and notes",IF(WEEKDAY(A26,2)=6,"Contest or timed mock · "&IF(E26<=3,"Revise 2 HLD concepts","2 full HLD designs")&" · Deep dive (Kafka, hashing...) · Gen AI catch-up",IF(WEEKDAY(A26,2)=7,"Re-solve the week’s hardest · "&IF(E26<=3,"Revise LLD concepts","1 LLD design")&" · Read mistakes log · Half day off","DSA 10:10 · "&IF(MOD(WEEKDAY(A26,2),2)=1,"HLD","LLD")&IF(E26<=3," concepts"," design")&" 3:30 · Gen AI 5:30 · DSA 8:00 · "&IF(A26<DATE(2026,10,23),"DE practice exam",IF(A26=DATE(2026,10,23),"DATABRICKS EXAM DAY","Behavioral story + Gen AI hands-on"))&" · Review"))))) -> DSA 10:10 · HLD design 3:30 · Gen AI 5:30 · DSA 8:00 · Behavioral story + Gen AI hands-on · Review | M26: =IF(C26="Yes",0,COUNTIF(G26:L26,"Yes")) -> 0 | N26: =IF(C26="Yes",0,6-COUNTIF(G26:L26,"—")) -> 6
A27: 46331 | B27: Thu | D27: =IF(C27="Yes","",ROW()-1-COUNTIF($C$2:C27,"Yes")) -> 26 | E27: =IF(C27="Yes","",IF(D27>57,"Buffer",MIN(8,INT((D27-1)/7)+1))) -> 4 | F27: =IF(C27="Yes","Day off: the plan shifts forward one day",IF(D27>57,"Buffer: revision, weak topics, mock interviews",IF(D27=1,"Kickoff: two pointers basics + 2 easy problems · HLD intro (client-server, scaling) · Set up NeetCode list and notes",IF(WEEKDAY(A27,2)=6,"Contest or timed mock · "&IF(E27<=3,"Revise 2 HLD concepts","2 full HLD designs")&" · Deep dive (Kafka, hashing...) · Gen AI catch-up",IF(WEEKDAY(A27,2)=7,"Re-solve the week’s hardest · "&IF(E27<=3,"Revise LLD concepts","1 LLD design")&" · Read mistakes log · Half day off","DSA 10:10 · "&IF(MOD(WEEKDAY(A27,2),2)=1,"HLD","LLD")&IF(E27<=3," concepts"," design")&" 3:30 · Gen AI 5:30 · DSA 8:00 · "&IF(A27<DATE(2026,10,23),"DE practice exam",IF(A27=DATE(2026,10,23),"DATABRICKS EXAM DAY","Behavioral story + Gen AI hands-on"))&" · Review"))))) -> DSA 10:10 · LLD design 3:30 · Gen AI 5:30 · DSA 8:00 · Behavioral story + Gen AI hands-on · Review | M27: =IF(C27="Yes",0,COUNTIF(G27:L27,"Yes")) -> 0 | N27: =IF(C27="Yes",0,6-COUNTIF(G27:L27,"—")) -> 6
A28: 46332 | B28: Fri | D28: =IF(C28="Yes","",ROW()-1-COUNTIF($C$2:C28,"Yes")) -> 27 | E28: =IF(C28="Yes","",IF(D28>57,"Buffer",MIN(8,INT((D28-1)/7)+1))) -> 4 | F28: =IF(C28="Yes","Day off: the plan shifts forward one day",IF(D28>57,"Buffer: revision, weak topics, mock interviews",IF(D28=1,"Kickoff: two pointers basics + 2 easy problems · HLD intro (client-server, scaling) · Set up NeetCode list and notes",IF(WEEKDAY(A28,2)=6,"Contest or timed mock · "&IF(E28<=3,"Revise 2 HLD concepts","2 full HLD designs")&" · Deep dive (Kafka, hashing...) · Gen AI catch-up",IF(WEEKDAY(A28,2)=7,"Re-solve the week’s hardest · "&IF(E28<=3,"Revise LLD concepts","1 LLD design")&" · Read mistakes log · Half day off","DSA 10:10 · "&IF(MOD(WEEKDAY(A28,2),2)=1,"HLD","LLD")&IF(E28<=3," concepts"," design")&" 3:30 · Gen AI 5:30 · DSA 8:00 · "&IF(A28<DATE(2026,10,23),"DE practice exam",IF(A28=DATE(2026,10,23),"DATABRICKS EXAM DAY","Behavioral story + Gen AI hands-on"))&" · Review"))))) -> DSA 10:10 · HLD design 3:30 · Gen AI 5:30 · DSA 8:00 · Behavioral story + Gen AI hands-on · Review | M28: =IF(C28="Yes",0,COUNTIF(G28:L28,"Yes")) -> 0 | N28: =IF(C28="Yes",0,6-COUNTIF(G28:L28,"—")) -> 6
A29: 46333 | B29: Sat | D29: =IF(C29="Yes","",ROW()-1-COUNTIF($C$2:C29,"Yes")) -> 28 | E29: =IF(C29="Yes","",IF(D29>57,"Buffer",MIN(8,INT((D29-1)/7)+1))) -> 4 | F29: =IF(C29="Yes","Day off: the plan shifts forward one day",IF(D29>57,"Buffer: revision, weak topics, mock interviews",IF(D29=1,"Kickoff: two pointers basics + 2 easy problems · HLD intro (client-server, scaling) · Set up NeetCode list and notes",IF(WEEKDAY(A29,2)=6,"Contest or timed mock · "&IF(E29<=3,"Revise 2 HLD concepts","2 full HLD designs")&" · Deep dive (Kafka, hashing...) · Gen AI catch-up",IF(WEEKDAY(A29,2)=7,"Re-solve the week’s hardest · "&IF(E29<=3,"Revise LLD concepts","1 LLD design")&" · Read mistakes log · Half day off","DSA 10:10 · "&IF(MOD(WEEKDAY(A29,2),2)=1,"HLD","LLD")&IF(E29<=3," concepts"," design")&" 3:30 · Gen AI 5:30 · DSA 8:00 · "&IF(A29<DATE(2026,10,23),"DE practice exam",IF(A29=DATE(2026,10,23),"DATABRICKS EXAM DAY","Behavioral story + Gen AI hands-on"))&" · Review"))))) -> Contest or timed mock · 2 full HLD designs · Deep dive (Kafka, hashing...) · Gen AI catch-up | J29: — | L29: — | M29: =IF(C29="Yes",0,COUNTIF(G29:L29,"Yes")) -> 0 | N29: =IF(C29="Yes",0,6-COUNTIF(G29:L29,"—")) -> 4
A30: 46334 | B30: Sun | D30: =IF(C30="Yes","",ROW()-1-COUNTIF($C$2:C30,"Yes")) -> 29 | E30: =IF(C30="Yes","",IF(D30>57,"Buffer",MIN(8,INT((D30-1)/7)+1))) -> 5 | F30: =IF(C30="Yes","Day off: the plan shifts forward one day",IF(D30>57,"Buffer: revision, weak topics, mock interviews",IF(D30=1,"Kickoff: two pointers basics + 2 easy problems · HLD intro (client-server, scaling) · Set up NeetCode list and notes",IF(WEEKDAY(A30,2)=6,"Contest or timed mock · "&IF(E30<=3,"Revise 2 HLD concepts","2 full HLD designs")&" · Deep dive (Kafka, hashing...) · Gen AI catch-up",IF(WEEKDAY(A30,2)=7,"Re-solve the week’s hardest · "&IF(E30<=3,"Revise LLD concepts","1 LLD design")&" · Read mistakes log · Half day off","DSA 10:10 · "&IF(MOD(WEEKDAY(A30,2),2)=1,"HLD","LLD")&IF(E30<=3," concepts"," design")&" 3:30 · Gen AI 5:30 · DSA 8:00 · "&IF(A30<DATE(2026,10,23),"DE practice exam",IF(A30=DATE(2026,10,23),"DATABRICKS EXAM DAY","Behavioral story + Gen AI hands-on"))&" · Review"))))) -> Re-solve the week’s hardest · 1 LLD design · Read mistakes log · Half day off | I30: — | J30: — | K30: — | M30: =IF(C30="Yes",0,COUNTIF(G30:L30,"Yes")) -> 0 | N30: =IF(C30="Yes",0,6-COUNTIF(G30:L30,"—")) -> 3
A31: 46335 | B31: Mon | D31: =IF(C31="Yes","",ROW()-1-COUNTIF($C$2:C31,"Yes")) -> 30 | E31: =IF(C31="Yes","",IF(D31>57,"Buffer",MIN(8,INT((D31-1)/7)+1))) -> 5 | F31: =IF(C31="Yes","Day off: the plan shifts forward one day",IF(D31>57,"Buffer: revision, weak topics, mock interviews",IF(D31=1,"Kickoff: two pointers basics + 2 easy problems · HLD intro (client-server, scaling) · Set up NeetCode list and notes",IF(WEEKDAY(A31,2)=6,"Contest or timed mock · "&IF(E31<=3,"Revise 2 HLD concepts","2 full HLD designs")&" · Deep dive (Kafka, hashing...) · Gen AI catch-up",IF(WEEKDAY(A31,2)=7,"Re-solve the week’s hardest · "&IF(E31<=3,"Revise LLD concepts","1 LLD design")&" · Read mistakes log · Half day off","DSA 10:10 · "&IF(MOD(WEEKDAY(A31,2),2)=1,"HLD","LLD")&IF(E31<=3," concepts"," design")&" 3:30 · Gen AI 5:30 · DSA 8:00 · "&IF(A31<DATE(2026,10,23),"DE practice exam",IF(A31=DATE(2026,10,23),"DATABRICKS EXAM DAY","Behavioral story + Gen AI hands-on"))&" · Review"))))) -> DSA 10:10 · HLD design 3:30 · Gen AI 5:30 · DSA 8:00 · Behavioral story + Gen AI hands-on · Review | M31: =IF(C31="Yes",0,COUNTIF(G31:L31,"Yes")) -> 0 | N31: =IF(C31="Yes",0,6-COUNTIF(G31:L31,"—")) -> 6
A32: 46336 | B32: Tue | D32: =IF(C32="Yes","",ROW()-1-COUNTIF($C$2:C32,"Yes")) -> 31 | E32: =IF(C32="Yes","",IF(D32>57,"Buffer",MIN(8,INT((D32-1)/7)+1))) -> 5 | F32: =IF(C32="Yes","Day off: the plan shifts forward one day",IF(D32>57,"Buffer: revision, weak topics, mock interviews",IF(D32=1,"Kickoff: two pointers basics + 2 easy problems · HLD intro (client-server, scaling) · Set up NeetCode list and notes",IF(WEEKDAY(A32,2)=6,"Contest or timed mock · "&IF(E32<=3,"Revise 2 HLD concepts","2 full HLD designs")&" · Deep dive (Kafka, hashing...) · Gen AI catch-up",IF(WEEKDAY(A32,2)=7,"Re-solve the week’s hardest · "&IF(E32<=3,"Revise LLD concepts","1 LLD design")&" · Read mistakes log · Half day off","DSA 10:10 · "&IF(MOD(WEEKDAY(A32,2),2)=1,"HLD","LLD")&IF(E32<=3," concepts"," design")&" 3:30 · Gen AI 5:30 · DSA 8:00 · "&IF(A32<DATE(2026,10,23),"DE practice exam",IF(A32=DATE(2026,10,23),"DATABRICKS EXAM DAY","Behavioral story + Gen AI hands-on"))&" · Review"))))) -> DSA 10:10 · LLD design 3:30 · Gen AI 5:30 · DSA 8:00 · Behavioral story + Gen AI hands-on · Review | M32: =IF(C32="Yes",0,COUNTIF(G32:L32,"Yes")) -> 0 | N32: =IF(C32="Yes",0,6-COUNTIF(G32:L32,"—")) -> 6
A33: 46337 | B33: Wed | D33: =IF(C33="Yes","",ROW()-1-COUNTIF($C$2:C33,"Yes")) -> 32 | E33: =IF(C33="Yes","",IF(D33>57,"Buffer",MIN(8,INT((D33-1)/7)+1))) -> 5 | F33: =IF(C33="Yes","Day off: the plan shifts forward one day",IF(D33>57,"Buffer: revision, weak topics, mock interviews",IF(D33=1,"Kickoff: two pointers basics + 2 easy problems · HLD intro (client-server, scaling) · Set up NeetCode list and notes",IF(WEEKDAY(A33,2)=6,"Contest or timed mock · "&IF(E33<=3,"Revise 2 HLD concepts","2 full HLD designs")&" · Deep dive (Kafka, hashing...) · Gen AI catch-up",IF(WEEKDAY(A33,2)=7,"Re-solve the week’s hardest · "&IF(E33<=3,"Revise LLD concepts","1 LLD design")&" · Read mistakes log · Half day off","DSA 10:10 · "&IF(MOD(WEEKDAY(A33,2),2)=1,"HLD","LLD")&IF(E33<=3," concepts"," design")&" 3:30 · Gen AI 5:30 · DSA 8:00 · "&IF(A33<DATE(2026,10,23),"DE practice exam",IF(A33=DATE(2026,10,23),"DATABRICKS EXAM DAY","Behavioral story + Gen AI hands-on"))&" · Review"))))) -> DSA 10:10 · HLD design 3:30 · Gen AI 5:30 · DSA 8:00 · Behavioral story + Gen AI hands-on · Review | M33: =IF(C33="Yes",0,COUNTIF(G33:L33,"Yes")) -> 0 | N33: =IF(C33="Yes",0,6-COUNTIF(G33:L33,"—")) -> 6
A34: 46338 | B34: Thu | D34: =IF(C34="Yes","",ROW()-1-COUNTIF($C$2:C34,"Yes")) -> 33 | E34: =IF(C34="Yes","",IF(D34>57,"Buffer",MIN(8,INT((D34-1)/7)+1))) -> 5 | F34: =IF(C34="Yes","Day off: the plan shifts forward one day",IF(D34>57,"Buffer: revision, weak topics, mock interviews",IF(D34=1,"Kickoff: two pointers basics + 2 easy problems · HLD intro (client-server, scaling) · Set up NeetCode list and notes",IF(WEEKDAY(A34,2)=6,"Contest or timed mock · "&IF(E34<=3,"Revise 2 HLD concepts","2 full HLD designs")&" · Deep dive (Kafka, hashing...) · Gen AI catch-up",IF(WEEKDAY(A34,2)=7,"Re-solve the week’s hardest · "&IF(E34<=3,"Revise LLD concepts","1 LLD design")&" · Read mistakes log · Half day off","DSA 10:10 · "&IF(MOD(WEEKDAY(A34,2),2)=1,"HLD","LLD")&IF(E34<=3," concepts"," design")&" 3:30 · Gen AI 5:30 · DSA 8:00 · "&IF(A34<DATE(2026,10,23),"DE practice exam",IF(A34=DATE(2026,10,23),"DATABRICKS EXAM DAY","Behavioral story + Gen AI hands-on"))&" · Review"))))) -> DSA 10:10 · LLD design 3:30 · Gen AI 5:30 · DSA 8:00 · Behavioral story + Gen AI hands-on · Review | M34: =IF(C34="Yes",0,COUNTIF(G34:L34,"Yes")) -> 0 | N34: =IF(C34="Yes",0,6-COUNTIF(G34:L34,"—")) -> 6
A35: 46339 | B35: Fri | D35: =IF(C35="Yes","",ROW()-1-COUNTIF($C$2:C35,"Yes")) -> 34 | E35: =IF(C35="Yes","",IF(D35>57,"Buffer",MIN(8,INT((D35-1)/7)+1))) -> 5 | F35: =IF(C35="Yes","Day off: the plan shifts forward one day",IF(D35>57,"Buffer: revision, weak topics, mock interviews",IF(D35=1,"Kickoff: two pointers basics + 2 easy problems · HLD intro (client-server, scaling) · Set up NeetCode list and notes",IF(WEEKDAY(A35,2)=6,"Contest or timed mock · "&IF(E35<=3,"Revise 2 HLD concepts","2 full HLD designs")&" · Deep dive (Kafka, hashing...) · Gen AI catch-up",IF(WEEKDAY(A35,2)=7,"Re-solve the week’s hardest · "&IF(E35<=3,"Revise LLD concepts","1 LLD design")&" · Read mistakes log · Half day off","DSA 10:10 · "&IF(MOD(WEEKDAY(A35,2),2)=1,"HLD","LLD")&IF(E35<=3," concepts"," design")&" 3:30 · Gen AI 5:30 · DSA 8:00 · "&IF(A35<DATE(2026,10,23),"DE practice exam",IF(A35=DATE(2026,10,23),"DATABRICKS EXAM DAY","Behavioral story + Gen AI hands-on"))&" · Review"))))) -> DSA 10:10 · HLD design 3:30 · Gen AI 5:30 · DSA 8:00 · Behavioral story + Gen AI hands-on · Review | M35: =IF(C35="Yes",0,COUNTIF(G35:L35,"Yes")) -> 0 | N35: =IF(C35="Yes",0,6-COUNTIF(G35:L35,"—")) -> 6
A36: 46340 | B36: Sat | D36: =IF(C36="Yes","",ROW()-1-COUNTIF($C$2:C36,"Yes")) -> 35 | E36: =IF(C36="Yes","",IF(D36>57,"Buffer",MIN(8,INT((D36-1)/7)+1))) -> 5 | F36: =IF(C36="Yes","Day off: the plan shifts forward one day",IF(D36>57,"Buffer: revision, weak topics, mock interviews",IF(D36=1,"Kickoff: two pointers basics + 2 easy problems · HLD intro (client-server, scaling) · Set up NeetCode list and notes",IF(WEEKDAY(A36,2)=6,"Contest or timed mock · "&IF(E36<=3,"Revise 2 HLD concepts","2 full HLD designs")&" · Deep dive (Kafka, hashing...) · Gen AI catch-up",IF(WEEKDAY(A36,2)=7,"Re-solve the week’s hardest · "&IF(E36<=3,"Revise LLD concepts","1 LLD design")&" · Read mistakes log · Half day off","DSA 10:10 · "&IF(MOD(WEEKDAY(A36,2),2)=1,"HLD","LLD")&IF(E36<=3," concepts"," design")&" 3:30 · Gen AI 5:30 · DSA 8:00 · "&IF(A36<DATE(2026,10,23),"DE practice exam",IF(A36=DATE(2026,10,23),"DATABRICKS EXAM DAY","Behavioral story + Gen AI hands-on"))&" · Review"))))) -> Contest or timed mock · 2 full HLD designs · Deep dive (Kafka, hashing...) · Gen AI catch-up | J36: — | L36: — | M36: =IF(C36="Yes",0,COUNTIF(G36:L36,"Yes")) -> 0 | N36: =IF(C36="Yes",0,6-COUNTIF(G36:L36,"—")) -> 4
A37: 46341 | B37: Sun | D37: =IF(C37="Yes","",ROW()-1-COUNTIF($C$2:C37,"Yes")) -> 36 | E37: =IF(C37="Yes","",IF(D37>57,"Buffer",MIN(8,INT((D37-1)/7)+1))) -> 6 | F37: =IF(C37="Yes","Day off: the plan shifts forward one day",IF(D37>57,"Buffer: revision, weak topics, mock interviews",IF(D37=1,"Kickoff: two pointers basics + 2 easy problems · HLD intro (client-server, scaling) · Set up NeetCode list and notes",IF(WEEKDAY(A37,2)=6,"Contest or timed mock · "&IF(E37<=3,"Revise 2 HLD concepts","2 full HLD designs")&" · Deep dive (Kafka, hashing...) · Gen AI catch-up",IF(WEEKDAY(A37,2)=7,"Re-solve the week’s hardest · "&IF(E37<=3,"Revise LLD concepts","1 LLD design")&" · Read mistakes log · Half day off","DSA 10:10 · "&IF(MOD(WEEKDAY(A37,2),2)=1,"HLD","LLD")&IF(E37<=3," concepts"," design")&" 3:30 · Gen AI 5:30 · DSA 8:00 · "&IF(A37<DATE(2026,10,23),"DE practice exam",IF(A37=DATE(2026,10,23),"DATABRICKS EXAM DAY","Behavioral story + Gen AI hands-on"))&" · Review"))))) -> Re-solve the week’s hardest · 1 LLD design · Read mistakes log · Half day off | I37: — | J37: — | K37: — | M37: =IF(C37="Yes",0,COUNTIF(G37:L37,"Yes")) -> 0 | N37: =IF(C37="Yes",0,6-COUNTIF(G37:L37,"—")) -> 3
A38: 46342 | B38: Mon | D38: =IF(C38="Yes","",ROW()-1-COUNTIF($C$2:C38,"Yes")) -> 37 | E38: =IF(C38="Yes","",IF(D38>57,"Buffer",MIN(8,INT((D38-1)/7)+1))) -> 6 | F38: =IF(C38="Yes","Day off: the plan shifts forward one day",IF(D38>57,"Buffer: revision, weak topics, mock interviews",IF(D38=1,"Kickoff: two pointers basics + 2 easy problems · HLD intro (client-server, scaling) · Set up NeetCode list and notes",IF(WEEKDAY(A38,2)=6,"Contest or timed mock · "&IF(E38<=3,"Revise 2 HLD concepts","2 full HLD designs")&" · Deep dive (Kafka, hashing...) · Gen AI catch-up",IF(WEEKDAY(A38,2)=7,"Re-solve the week’s hardest · "&IF(E38<=3,"Revise LLD concepts","1 LLD design")&" · Read mistakes log · Half day off","DSA 10:10 · "&IF(MOD(WEEKDAY(A38,2),2)=1,"HLD","LLD")&IF(E38<=3," concepts"," design")&" 3:30 · Gen AI 5:30 · DSA 8:00 · "&IF(A38<DATE(2026,10,23),"DE practice exam",IF(A38=DATE(2026,10,23),"DATABRICKS EXAM DAY","Behavioral story + Gen AI hands-on"))&" · Review"))))) -> DSA 10:10 · HLD design 3:30 · Gen AI 5:30 · DSA 8:00 · Behavioral story + Gen AI hands-on · Review | M38: =IF(C38="Yes",0,COUNTIF(G38:L38,"Yes")) -> 0 | N38: =IF(C38="Yes",0,6-COUNTIF(G38:L38,"—")) -> 6
A39: 46343 | B39: Tue | D39: =IF(C39="Yes","",ROW()-1-COUNTIF($C$2:C39,"Yes")) -> 38 | E39: =IF(C39="Yes","",IF(D39>57,"Buffer",MIN(8,INT((D39-1)/7)+1))) -> 6 | F39: =IF(C39="Yes","Day off: the plan shifts forward one day",IF(D39>57,"Buffer: revision, weak topics, mock interviews",IF(D39=1,"Kickoff: two pointers basics + 2 easy problems · HLD intro (client-server, scaling) · Set up NeetCode list and notes",IF(WEEKDAY(A39,2)=6,"Contest or timed mock · "&IF(E39<=3,"Revise 2 HLD concepts","2 full HLD designs")&" · Deep dive (Kafka, hashing...) · Gen AI catch-up",IF(WEEKDAY(A39,2)=7,"Re-solve the week’s hardest · "&IF(E39<=3,"Revise LLD concepts","1 LLD design")&" · Read mistakes log · Half day off","DSA 10:10 · "&IF(MOD(WEEKDAY(A39,2),2)=1,"HLD","LLD")&IF(E39<=3," concepts"," design")&" 3:30 · Gen AI 5:30 · DSA 8:00 · "&IF(A39<DATE(2026,10,23),"DE practice exam",IF(A39=DATE(2026,10,23),"DATABRICKS EXAM DAY","Behavioral story + Gen AI hands-on"))&" · Review"))))) -> DSA 10:10 · LLD design 3:30 · Gen AI 5:30 · DSA 8:00 · Behavioral story + Gen AI hands-on · Review | M39: =IF(C39="Yes",0,COUNTIF(G39:L39,"Yes")) -> 0 | N39: =IF(C39="Yes",0,6-COUNTIF(G39:L39,"—")) -> 6
A40: 46344 | B40: Wed | D40: =IF(C40="Yes","",ROW()-1-COUNTIF($C$2:C40,"Yes")) -> 39 | E40: =IF(C40="Yes","",IF(D40>57,"Buffer",MIN(8,INT((D40-1)/7)+1))) -> 6 | F40: =IF(C40="Yes","Day off: the plan shifts forward one day",IF(D40>57,"Buffer: revision, weak topics, mock interviews",IF(D40=1,"Kickoff: two pointers basics + 2 easy problems · HLD intro (client-server, scaling) · Set up NeetCode list and notes",IF(WEEKDAY(A40,2)=6,"Contest or timed mock · "&IF(E40<=3,"Revise 2 HLD concepts","2 full HLD designs")&" · Deep dive (Kafka, hashing...) · Gen AI catch-up",IF(WEEKDAY(A40,2)=7,"Re-solve the week’s hardest · "&IF(E40<=3,"Revise LLD concepts","1 LLD design")&" · Read mistakes log · Half day off","DSA 10:10 · "&IF(MOD(WEEKDAY(A40,2),2)=1,"HLD","LLD")&IF(E40<=3," concepts"," design")&" 3:30 · Gen AI 5:30 · DSA 8:00 · "&IF(A40<DATE(2026,10,23),"DE practice exam",IF(A40=DATE(2026,10,23),"DATABRICKS EXAM DAY","Behavioral story + Gen AI hands-on"))&" · Review"))))) -> DSA 10:10 · HLD design 3:30 · Gen AI 5:30 · DSA 8:00 · Behavioral story + Gen AI hands-on · Review | M40: =IF(C40="Yes",0,COUNTIF(G40:L40,"Yes")) -> 0 | N40: =IF(C40="Yes",0,6-COUNTIF(G40:L40,"—")) -> 6
...

Sheet DSA Problems
A1: # | B1: Topic | C1: When | D1: Problem (NeetCode) | E1: LeetCode | F1: Difficulty | G1: List | H1: Status | I1: Date solved | J1: Revised | K1: Notes
A2: 1 | B2: Arrays & Hashing | C2: Week 1 (quick pass) | D2: Contains Duplicate | E2: Open | F2: Easy | G2: NeetCode 150 | H2: Not started
A3: 2 | B3: Arrays & Hashing | C3: Week 1 (quick pass) | D3: Valid Anagram | E3: Open | F3: Easy | G3: NeetCode 150 | H3: Not started
A4: 3 | B4: Arrays & Hashing | C4: Week 1 (quick pass) | D4: Two Sum | E4: Open | F4: Easy | G4: NeetCode 150 | H4: Not started
A5: 4 | B5: Arrays & Hashing | C5: Week 1 (quick pass) | D5: Group Anagrams | E5: Open | F5: Medium | G5: NeetCode 150 | H5: Not started
A6: 5 | B6: Arrays & Hashing | C6: Week 1 (quick pass) | D6: Top K Frequent Elements | E6: Open | F6: Medium | G6: NeetCode 150 | H6: Not started
A7: 6 | B7: Arrays & Hashing | C7: Week 1 (quick pass) | D7: Encode and Decode Strings | E7: Open | F7: Medium | G7: NeetCode 150 | H7: Not started
A8: 7 | B8: Arrays & Hashing | C8: Week 1 (quick pass) | D8: Product of Array Except Self | E8: Open | F8: Medium | G8: NeetCode 150 | H8: Not started
A9: 8 | B9: Arrays & Hashing | C9: Week 1 (quick pass) | D9: Valid Sudoku | E9: Open | F9: Medium | G9: NeetCode 150 | H9: Not started
A10: 9 | B10: Arrays & Hashing | C10: Week 1 (quick pass) | D10: Longest Consecutive Sequence | E10: Open | F10: Medium | G10: NeetCode 150 | H10: Not started
A11: 10 | B11: Arrays & Hashing | C11: Week 1 (quick pass) | D11: Concatenation of Array | E11: Open | F11: Easy | G11: Stretch (250) | H11: Not started
A12: 11 | B12: Arrays & Hashing | C12: Week 1 (quick pass) | D12: Longest Common Prefix | E12: Open | F12: Easy | G12: Stretch (250) | H12: Not started
A13: 12 | B13: Arrays & Hashing | C13: Week 1 (quick pass) | D13: Remove Element | E13: Open | F13: Easy | G13: Stretch (250) | H13: Not started
... A251: 250 | B251: Bit Manipulation | C251: Week 8 or stretch | D251: Minimum Array End | E251: Open | F251: Medium | G251: Stretch (250) | H251: Not started

Sheet Weekly Plan
A1: Week | B1: Dates (auto) | C1: Area | D1: Topic | E1: Type | F1: Done | G1: Notes
A2: 1 | B2: =TEXT(INDEX('Daily Log'!$A$2:$A$93,MATCH(1,'Daily Log'!$D$2:$D$93,0)),"d mmm")&" – "&TEXT(INDEX('Daily Log'!$A$2:$A$93,MATCH(7,'Daily Log'!$D$2:$D$93,0)),"d mmm") -> 11 Oct – 17 Oct | C2: DSA | D2: Arrays & Hashing: quick pass of the 9 core problems | E2: Practice
A3: 1 | B3: =TEXT(INDEX('Daily Log'!$A$2:$A$93,MATCH(1,'Daily Log'!$D$2:$D$93,0)),"d mmm")&" – "&TEXT(INDEX('Daily Log'!$A$2:$A$93,MATCH(7,'Daily Log'!$D$2:$D$93,0)),"d mmm") -> 11 Oct – 17 Oct | C3: DSA | D3: Two pointers | E3: Practice
A4: 1 | B4: =TEXT(INDEX('Daily Log'!$A$2:$A$93,MATCH(1,'Daily Log'!$D$2:$D$93,0)),"d mmm")&" – "&TEXT(INDEX('Daily Log'!$A$2:$A$93,MATCH(7,'Daily Log'!$D$2:$D$93,0)),"d mmm") -> 11 Oct – 17 Oct | C4: DSA | D4: Sliding window | E4: Practice
A5: 1 | B5: =TEXT(INDEX('Daily Log'!$A$2:$A$93,MATCH(1,'Daily Log'!$D$2:$D$93,0)),"d mmm")&" – "&TEXT(INDEX('Daily Log'!$A$2:$A$93,MATCH(7,'Daily Log'!$D$2:$D$93,0)),"d mmm") -> 11 Oct – 17 Oct | C5: DSA | D5: Stack | E5: Practice
